Workbook

Sheet UAT Checklist
A1: Sr No | B1: Module | C1: Section | D1: Test Case ID | E1: Checkpoint | F1: Steps | G1: Expected Result | H1: Priority | I1: Rushikesh | J1: Aditi | K1: Siddhi | L1: Chinmay | M1: Tanishq | N1: Overall Status | O1: Remarks / Defect ID
A2: 1 | B2: Authentication & Session | C2: Login | D2: 1.1.1 | E2: Valid login with OTP | F2: Enter valid username + password + OTP → Submit | G2: Session created, redirect to dashboard, LoginLog recorded | H2: Critical | I2: ☑ | J2: ☐ | K2: ☑ | L2: ☐ | M2: ☐ | N2: =IF(COUNTIF(I2:L2,"☑")=4,"Complete",IF(COUNTIF(I2:L2,"☑")>0,"In Progress","Pending")) -> In Progress
A3: 2 | B3: Authentication & Session | C3: Login | D3: 1.1.2 | E3: Wrong password | F3: Enter valid username + wrong password → Submit | G3: "Invalid credentials" error, failedLoginAttempts incremented | H3: Critical | I3: ☑ | J3: ☐ | K3: ☑ | L3: ☐ | M3: ☐ | N3: =IF(COUNTIF(I3:L3,"☑")=4,"Complete",IF(COUNTIF(I3:L3,"☑")>0,"In Progress","Pending")) -> In Progress
A4: 3 | B4: Authentication & Session | C4: Login | D4: 1.1.3 | E4: Wrong OTP | F4: Enter valid creds + wrong OTP → Submit | G4: "Invalid OTP" error | H4: Critical | I4: ☑ | J4: ☐ | K4: ☑ | L4: ☐ | M4: ☐ | N4: =IF(COUNTIF(I4:L4,"☑")=4,"Complete",IF(COUNTIF(I4:L4,"☑")>0,"In Progress","Pending")) -> In Progress
A5: 4 | B5: Authentication & Session | C5: Login | D5: 1.1.4 | E5: Account lockout after 5 attempts | F5: Enter wrong password 5 times | G5: Account locked for 15 min, "Account locked" message | H5: Critical | I5: ☐ | J5: ☐ | K5: ☐ | L5: ☐ | M5: ☐ | N5: =IF(COUNTIF(I5:L5,"☑")=4,"Complete",IF(COUNTIF(I5:L5,"☑")>0,"In Progress","Pending")) -> Pending | O5: I entered 5 times wrong password but Accountant is not locked
A6: 5 | B6: Authentication & Session | C6: Login | D6: 1.1.5 | E6: Login while locked | F6: Wait < 15 min, enter correct creds | G6: "Account locked" even with correct creds | H6: High | I6: ☐ | J6: ☐ | K6: ☐ | L6: ☐ | M6: ☐ | N6: =IF(COUNTIF(I6:L6,"☑")=4,"Complete",IF(COUNTIF(I6:L6,"☑")>0,"In Progress","Pending")) -> Pending | O6: Account wasn’t locked, so I didn’t check
A7: 6 | B7: Authentication & Session | C7: Login | D7: 1.1.6 | E7: Login after lockout expires | F7: Wait > 15 min, enter correct creds | G7: Login succeeds, failedLoginAttempts reset | H7: High | I7: ☐ | J7: ☐ | K7: ☐ | L7: ☐ | M7: ☐ | N7: =IF(COUNTIF(I7:L7,"☑")=4,"Complete",IF(COUNTIF(I7:L7,"☑")>0,"In Progress","Pending")) -> Pending | O7: Account wasn’t locked, so I didn’t check
A8: 7 | B8: Authentication & Session | C8: Login | D8: 1.1.7 | E8: Expired password (90 days) | F8: Login with creds where passwordChangedAt > 90 days | G8: Login succeeds but mustChangePassword=true, redirect to /account/security | H8: High | I8: ☐ | J8: ☐ | K8: ☐ | L8: ☐ | M8: ☐ | N8: =IF(COUNTIF(I8:L8,"☑")=4,"Complete",IF(COUNTIF(I8:L8,"☑")>0,"In Progress","Pending")) -> Pending
A9: 8 | B9: Authentication & Session | C9: Login | D9: 1.1.8 | E9: Inactive user login | F9: Deactivate user, attempt login | G9: Login rejected | H9: Critical | I9: ☐ | J9: ☐ | K9: ☐ | L9: ☐ | M9: ☐ | N9: =IF(COUNTIF(I9:L9,"☑")=4,"Complete",IF(COUNTIF(I9:L9,"☑")>0,"In Progress","Pending")) -> Pending | O9: I didn’t check it because deactivation was not working
A10: 9 | B10: Authentication & Session | C10: Login | D10: 1.1.9 | E10: Empty username | F10: Submit with blank username | G10: Validation error | H10: Medium | I10: ☑ | J10: ☐ | K10: ☑ | L10: ☐ | M10: ☐ | N10: =IF(COUNTIF(I10:L10,"☑")=4,"Complete",IF(COUNTIF(I10:L10,"☑")>0,"In Progress","Pending")) -> In Progress
A11: 10 | B11: Authentication & Session | C11: Login | D11: 1.1.10 | E11: Empty password | F11: Submit with blank password | G11: Validation error | H11: Medium | I11: ☑ | J11: ☐ | K11: ☑ | L11: ☐ | M11: ☐ | N11: =IF(COUNTIF(I11:L11,"☑")=4,"Complete",IF(COUNTIF(I11:L11,"☑")>0,"In Progress","Pending")) -> In Progress
A12: 11 | B12: Authentication & Session | C12: Login | D12: 1.1.11 | E12: Late login detection | F12: Login after work start time + grace minutes (non-admin) | G12: LoginLog recorded with isLate=true | H12: High | I12: ☑ | J12: ☐ | K12: ☑ | L12: ☐ | M12: ☐ | N12: =IF(COUNTIF(I12:L12,"☑")=4,"Complete",IF(COUNTIF(I12:L12,"☑")>0,"In Progress","Pending")) -> In Progress
A13: 12 | B13: Authentication & Session | C13: Login | D13: 1.1.12 | E13: On-time login | F13: Login before work start time + grace (non-admin) | G13: LoginLog with isLate=false | H13: High | I13: ☐ | J13: ☐ | K13: ☐ | L13: ☐ | M13: ☐ | N13: =IF(COUNTIF(I13:L13,"☑")=4,"Complete",IF(COUNTIF(I13:L13,"☑")>0,"In Progress","Pending")) -> Pending
A14: 13 | B14: Authentication & Session | C14: Login | D14: 1.1.13 | E14: Admin login is never late | F14: Admin logs in after start time | G14: LoginLog with isLate=false (admins exempt) | H14: Medium | I14: ☐ | J14: ☐ | K14: ☐ | L14: ☐ | M14: ☐ | N14: =IF(COUNTIF(I14:L14,"☑")=4,"Complete",IF(COUNTIF(I14:L14,"☑")>0,"In Progress","Pending")) -> Pending
A15: 14 | B15: Authentication & Session | C15: Logout | D15: 1.2.1 | E15: Normal logout | F15: Click logout | G15: Session destroyed, LoginLog updated with logoutAt | H15: High | I15: ☐ | J15: ☐ | K15: ☑ | L15: ☐ | M15: ☐ | N15: =IF(COUNTIF(I15:L15,"☑")=4,"Complete",IF(COUNTIF(I15:L15,"☑")>0,"In Progress","Pending")) -> In Progress
A16: 15 | B16: Authentication & Session | C16: Logout | D16: 1.2.2 | E16: Record-logout API | F16: POST /api/auth/record-logout | G16: logoutAt timestamp updated on latest LoginLog | H16: High | I16: ☐ | J16: ☐ | K16: ☐ | L16: ☐ | M16: ☐ | N16: =IF(COUNTIF(I16:L16,"☑")=4,"Complete",IF(COUNTIF(I16:L16,"☑")>0,"In Progress","Pending")) -> Pending
A17: 16 | B17: Authentication & Session | C17: Password Reset | D17: 1.3.1 | E17: Request password reset | F17: Go to /forgot, enter valid email/username | G17: Reset email sent, PasswordResetToken created | H17: High | I17: ☐ | J17: ☐ | K17: ☐ | L17: ☐ | M17: ☐ | N17: =IF(COUNTIF(I17:L17,"☑")=4,"Complete",IF(COUNTIF(I17:L17,"☑")>0,"In Progress","Pending")) -> Pending | O17: "something went wrong" errror msg displayed
A18: 17 | B18: Authentication & Session | C18: Password Reset | D18: 1.3.2 | E18: Invalid identifier | F18: Enter non-existent email | G18: Vague success message (no user enumeration) | H18: High | I18: ☐ | J18: ☐ | K18: ☐ | L18: ☐ | M18: ☐ | N18: =IF(COUNTIF(I18:L18,"☑")=4,"Complete",IF(COUNTIF(I18:L18,"☑")>0,"In Progress","Pending")) -> Pending | O18: "something went wrong" errror msg displayed
A19: 18 | B19: Authentication & Session | C19: Password Reset | D19: 1.3.3 | E19: Complete reset with valid token | F19: Follow reset link, enter new password | G19: Password updated, token consumed | H19: High | I19: ☐ | J19: ☐ | K19: ☐ | L19: ☐ | M19: ☐ | N19: =IF(COUNTIF(I19:L19,"☑")=4,"Complete",IF(COUNTIF(I19:L19,"☑")>0,"In Progress","Pending")) -> Pending | O19: "something went wrong" errror msg displayed
A20: 19 | B20: Authentication & Session | C20: Password Reset | D20: 1.3.4 | E20: Expired/invalid token | F20: Use expired or tampered token | G20: Error message | H20: High | I20: ☐ | J20: ☐ | K20: ☐ | L20: ☐ | M20: ☐ | N20: =IF(COUNTIF(I20:L20,"☑")=4,"Complete",IF(COUNTIF(I20:L20,"☑")>0,"In Progress","Pending")) -> Pending
A21: 20 | B21: Authentication & Session | C21: Password Reset | D21: 1.3.5 | E21: Password mismatch | F21: New password ≠ confirm password | G21: Validation error | H21: Medium | I21: ☐ | J21: ☐ | K21: ☐ | L21: ☐ | M21: ☐ | N21: =IF(COUNTIF(I21:L21,"☑")=4,"Complete",IF(COUNTIF(I21:L21,"☑")>0,"In Progress","Pending")) -> Pending
A22: 21 | B22: Authentication & Session | C22: Session Management | D22: 1.4.1 | E22: Session idle timeout | F22: Leave session idle beyond configured timeout | G22: Redirect to login | H22: High | I22: ☐ | J22: ☐ | K22: ☐ | L22: ☐ | M22: ☐ | N22: =IF(COUNTIF(I22:L22,"☑")=4,"Complete",IF(COUNTIF(I22:L22,"☑")>0,"In Progress","Pending")) -> Pending
A23: 22 | B23: Authentication & Session | C23: Session Management | D23: 1.4.2 | E23: Forced password change blocks navigation | F23: User with mustChangePassword=true tries to navigate away from /account/security | G23: Redirected back to /account/security | H23: High | I23: ☐ | J23: ☐ | K23: ☐ | L23: ☐ | M23: ☐ | N23: =IF(COUNTIF(I23:L23,"☑")=4,"Complete",IF(COUNTIF(I23:L23,"☑")>0,"In Progress","Pending")) -> Pending
A24: 23 | B24: User Management | C24: Create User (saveUser) | D24: 2.1.1 | E24: Create user with all fields | F24: Fill fullName, email, username, role, phone, employeeCode, parentId, joiningDate, password | G24: User created, audit logged, revalidate /users | H24: Critical | I24: ☐ | J24: ☐ | K24: ☐ | L24: ☐ | M24: ☐ | N24: =IF(COUNTIF(I24:L24,"☑")=4,"Complete",IF(COUNTIF(I24:L24,"☑")>0,"In Progress","Pending")) -> Pending | O24: "something went wrong" errror msg displayed
A25: 24 | B25: User Management | C25: Create User (saveUser) | D25: 2.1.2 | E25: Missing full name | F25: Omit fullName | G25: Error: "Full name is required." | H25: High | I25: ☑ | J25: ☐ | K25: ☐ | L25: ☐ | M25: ☐ | N25: =IF(COUNTIF(I25:L25,"☑")=4,"Complete",IF(COUNTIF(I25:L25,"☑")>0,"In Progress","Pending")) -> In Progress | O25: not proper msg will be generate "please fill in this filed" this error msg will be generate
A26: 25 | B26: User Management | C26: Create User (saveUser) | D26: 2.1.3 | E26: Missing email | F26: Omit email | G26: Error: "Email is required." | H26: High | I26: ☑ | J26: ☐ | K26: ☐ | L26: ☐ | M26: ☐ | N26: =IF(COUNTIF(I26:L26,"☑")=4,"Complete",IF(COUNTIF(I26:L26,"☑")>0,"In Progress","Pending")) -> In Progress | O26: not proper msg will be generate "please fill in this filed" this error msg will be generate
A27: 26 | B27: User Management | C27: Create User (saveUser) | D27: 2.1.4 | E27: Missing username | F27: Omit username | G27: Error: "Username is required." | H27: High | I27: ☑ | J27: ☐ | K27: ☐ | L27: ☐ | M27: ☐ | N27: =IF(COUNTIF(I27:L27,"☑")=4,"Complete",IF(COUNTIF(I27:L27,"☑")>0,"In Progress","Pending")) -> In Progress | O27: not proper msg will be generate "please fill in this filed" this error msg will be generate
A28: 27 | B28: User Management | C28: Create User (saveUser) | D28: 2.1.5 | E28: Invalid role | F28: Set role to "SUPERADMIN" | G28: Error: "Select a valid role." | H28: High | I28: ☑ | J28: ☐ | K28: ☐ | L28: ☐ | M28: ☐ | N28: =IF(COUNTIF(I28:L28,"☑")=4,"Complete",IF(COUNTIF(I28:L28,"☑")>0,"In Progress","Pending")) -> In Progress | O28: not proper msg will be generate "please select an item in the list" this error msg will be generate
A29: 28 | B29: User Management | C29: Create User (saveUser) | D29: 2.1.6 | E29: Missing password on create | F29: Omit password for new user | G29: Error: "Password is required." | H29: High | I29: ☑ | J29: ☐ | K29: ☐ | L29: ☐ | M29: ☐ | N29: =IF(COUNTIF(I29:L29,"☑")=4,"Complete",IF(COUNTIF(I29:L29,"☑")>0,"In Progress","Pending")) -> In Progress | O29: not proper msg will be generate "please fill in this filed" this error msg will be generate
A30: 29 | B30: User Management | C30: Create User (saveUser) | D30: 2.1.7 | E30: Duplicate email | F30: Use email already in database | G30: Prisma unique constraint error | H30: High | I30: ☐ | J30: ☐ | K30: ☐ | L30: ☐ | M30: ☐ | N30: =IF(COUNTIF(I30:L30,"☑")=4,"Complete",IF(COUNTIF(I30:L30,"☑")>0,"In Progress","Pending")) -> Pending | O30: "something went wrong" errror msg displayed
A31: 30 | B31: User Management | C31: Create User (saveUser) | D31: 2.1.8 | E31: Duplicate username | F31: Use username already in database | G31: Prisma unique constraint error | H31: High | I31: ☐ | J31: ☐ | K31: ☐ | L31: ☐ | M31: ☐ | N31: =IF(COUNTIF(I31:L31,"☑")=4,"Complete",IF(COUNTIF(I31:L31,"☑")>0,"In Progress","Pending")) -> Pending | O31: "something went wrong" errror msg displayed
A32: 31 | B32: User Management | C32: Create User (saveUser) | D32: 2.1.9 | E32: Create with each valid role | F32: Test ADMIN, MANAGER, TEAM_LEADER, RECRUITER, ACCOUNTANT | G32: Each role accepted | H32: High | I32: ☑ | J32: ☐ | K32: ☐ | L32: ☐ | M32: ☐ | N32: =IF(COUNTIF(I32:L32,"☑")=4,"Complete",IF(COUNTIF(I32:L32,"☑")>0,"In Progress","Pending")) -> In Progress
A33: 32 | B33: User Management | C33: Create User (saveUser) | D33: 2.1.10 | E33: Optional fields omitted | F33: Create with only required fields | G33: User created with null optional fields | H33: Medium | I33: ☐ | J33: ☐ | K33: ☐ | L33: ☐ | M33: ☐ | N33: =IF(COUNTIF(I33:L33,"☑")=4,"Complete",IF(COUNTIF(I33:L33,"☑")>0,"In Progress","Pending")) -> Pending | O33: "something went wrong" errror msg displayed
A34: 33 | B34: User Management | C34: Update User (saveUser with userId) | D34: 2.2.1 | E34: Update name and role | F34: Set userId + new fullName + new role | G34: User updated, audit logs before/after | H34: High | I34: ☐ | J34: ☐ | K34: ☐ | L34: ☐ | M34: ☐ | N34: =IF(COUNTIF(I34:L34,"☑")=4,"Complete",IF(COUNTIF(I34:L34,"☑")>0,"In Progress","Pending")) -> Pending | O34: "something went wrong" errror msg displayed
A35: 34 | B35: User Management | C35: Update User (saveUser with userId) | D35: 2.2.2 | E35: Update password | F35: Set new password on existing user | G35: hashedPassword updated, passwordChangedAt reset, failedLoginAttempts=0, lockedUntil=null | H35: High | I35: ☐ | J35: ☐ | K35: ☐ | L35: ☐ | M35: ☐ | N35: =IF(COUNTIF(I35:L35,"☑")=4,"Complete",IF(COUNTIF(I35:L35,"☑")>0,"In Progress","Pending")) -> Pending | O35: "something went wrong" errror msg displayed
A36: 35 | B36: User Management | C36: Update User (saveUser with userId) | D36: 2.2.3 | E36: Update without password | F36: Omit password field on existing user | G36: Password unchanged | H36: Medium | I36: ☐ | J36: ☐ | K36: ☐ | L36: ☐ | M36: ☐ | N36: =IF(COUNTIF(I36:L36,"☑")=4,"Complete",IF(COUNTIF(I36:L36,"☑")>0,"In Progress","Pending")) -> Pending | O36: "something went wrong" errror msg displayed
A37: 36 | B37: User Management | C37: Update User (saveUser with userId) | D37: 2.2.4 | E37: Non-existent userId | F37: Set userId to invalid ID | G37: Prisma error (record not found) | H37: Medium | I37: ☐ | J37: ☐ | K37: ☐ | L37: ☐ | M37: ☐ | N37: =IF(COUNTIF(I37:L37,"☑")=4,"Complete",IF(COUNTIF(I37:L37,"☑")>0,"In Progress","Pending")) -> Pending | O37: "something went wrong" errror msg displayed
A38: 37 | B38: User Management | C38: Toggle User (toggleUser) | D38: 2.3.1 | E38: Deactivate user | F38: toggleUser(userId, false) | G38: isActive=false, audit logged | H38: High | I38: ☐ | J38: ☐ | K38: ☐ | L38: ☐ | M38: ☐ | N38: =IF(COUNTIF(I38:L38,"☑")=4,"Complete",IF(COUNTIF(I38:L38,"☑")>0,"In Progress","Pending")) -> Pending | O38: users:1 Failed to load resource: the server responded with a status of 500 ()
A39: 38 | B39: User Management | C39: Toggle User (toggleUser) | D39: 2.3.2 | E39: Reactivate user | F39: toggleUser(userId, true) | G39: isActive=true, audit logged | H39: High | I39: ☐ | J39: ☐ | K39: ☐ | L39: ☐ | M39: ☐ | N39: =IF(COUNTIF(I39:L39,"☑")=4,"Complete",IF(COUNTIF(I39:L39,"☑")>0,"In Progress","Pending")) -> Pending
A40: 39 | B40: User Management | C40: Toggle User (toggleUser) | D40: 2.3.3 | E40: Toggle non-existent user | F40: Pass invalid userId | G40: Error: "User not found." | H40: Medium | I40: ☐ | J40: ☐ | K40: ☐ | L40: ☐ | M40: ☐ | N40: =IF(COUNTIF(I40:L40,"☑")=4,"Complete",IF(COUNTIF(I40:L40,"☑")>0,"In Progress","Pending")) -> Pending
...

Sheet Summary
A1: Tester | B1: Completed | C1: Pending | D1: Total Checkpoints | E1: Completion %
A2: Manjali | B2: =COUNTIF('UAT Checklist'!I:I,"☑") -> 138 | C2: =COUNTIF('UAT Checklist'!I:I,"☐") -> 190 | D2: 328 | E2: =IF(D2=0,0,B2/D2) -> 0.42073171
A3: Aditi | B3: =COUNTIF('UAT Checklist'!J:J,"☑") -> 0 | C3: =COUNTIF('UAT Checklist'!J:J,"☐") -> 328 | D3: 328 | E3: =IF(D3=0,0,B3/D3) -> 0
A4: Siddhi | B4: =COUNTIF('UAT Checklist'!K:K,"☑") -> 8 | C4: =COUNTIF('UAT Checklist'!K:K,"☐") -> 320 | D4: 328 | E4: =IF(D4=0,0,B4/D4) -> 0.024390244
A5: Chinmay | B5: =COUNTIF('UAT Checklist'!L:L,"☑") -> 0 | C5: =COUNTIF('UAT Checklist'!L:L,"☐") -> 328 | D5: 328 | E5: =IF(D5=0,0,B5/D5) -> 0
A7: Overall complete rows | B7: =COUNTIF('UAT Checklist'!N:N,"Complete") -> 0
A8: Overall pending rows | B8: =COUNTIF('UAT Checklist'!N:N,"Pending") -> 189
A9: Overall in-progress rows | B9: =COUNTIF('UAT Checklist'!N:N,"In Progress") -> 139
A10: Source file | B10: ADMIN_TEST_CASES.md
A11: Note | B11: Use the dropdown in each tester column to switch unchecked to checked.
